<?xml version="1.0"?>
<!-- =================================================================================== -->
<!-- |    This document was autogenerated by xacro from dual_arm.xacro                 | -->
<!-- |    EDITING THIS FILE BY HAND IS NOT RECOMMENDED                                 | -->
<!-- =================================================================================== -->
<robot name="dual_arm">
    <link name="world"/>
    <!-- wall behind robots -->
    <link name="base">
        <visual>
            <!-- y is half the y dimension of the box, plus 0.508 -->
            <!-- z is half the z dimension of the box, plus 0.356 -->
            <origin rpy="0 0 0" xyz="0 0.608 1.356" />
            <!-- <origin xyz="1.34724341 0.01972794 0.66630936" rpy="1.56466 -8.63678e-05 1.57138"
            /> -->
            <geometry>
                <box size="2 0.2 2" />
            </geometry>
            <material name="White">
                <color rgba="1.0 1.0 1.0 1.0" />
            </material>
        </visual>
        <collision>
            <origin rpy="0 0 0" xyz="0 0.608 1.356" />
            <!-- <origin xyz="1.34724341 0.01972794 0.66630936" rpy="1.56466 -8.63678e-05 1.57138"
            /> -->
            <geometry>
                <box size="2 0.2 2" />
            </geometry>
        </collision>
        <inertial>
            <origin rpy="0.0 0.0 0.0" xyz="0.0 0.0 0.0" />
            <mass value="10.0" />
            <inertia ixx="0.001" ixy="0.0" ixz="0.001" iyy="0.0" iyz="0.0" izz="0.001" />
        </inertial>
    </link>
    <!-- table -->
    <link name="table">
        <visual>
            <origin rpy="0 0 0" xyz="0 0 1.22" />
            <geometry>
                <!-- <box size="1.82 0.76 0.032" /> -->
                <box size="1.82 1.0 0.032" />
            </geometry>
            <material name="White">
                <color rgba="1.0 1.0 1.0 1.0" />
            </material>
        </visual>
        <collision>
            <origin rpy="0 0 0" xyz="0 0 1.22" />
            <geometry>
                <box size="1.82 0.76 0.032" />
            </geometry>
        </collision>
        <inertial>
            <origin rpy="0.0 0.0 0.0" xyz="0.0 0.0 0.0" />
            <mass value="10.0" />
            <inertia ixx="0.001" ixy="0.0" ixz="0.001" iyy="0.0" iyz="0.0" izz="0.001" />
        </inertial>
    </link>
    <joint name="base_to_world" type="fixed">
        <parent link="world" />
        <child link="base" />
        <!-- <origin xyz="0.58911788 1.30589175 0.01335737" rpy="0.09474559577728693
        -1.5646323542124896 -1.6656300811826108" /> -->
        <origin rpy="-1.56466 8.63678e-05 -1.57138" xyz="-0.05011849 -0.00497215  0.01868442" />
        <!-- <origin xyz="1.34724341 0.01972794 0.66630936" rpy="1.56466 -8.63678e-05 1.57138" /> -->
        <origin rpy="0.0 0.0 0.0" xyz="0.0 0.0 0.0" />
    </joint>
    <joint name="table_to_world" type="fixed">
        <parent link="world" />
        <child link="table" />
        <!-- <origin xyz="0.58911788 1.30589175 0.01335737" rpy="0.09474559577728693
        -1.5646323542124896 -1.6656300811826108" /> -->
        <origin rpy="-1.56466 8.63678e-05 -1.57138" xyz="0.02 -0.00497215  0.01868442" />
        <!-- <origin xyz="1.34724341 0.01972794 0.66630936" rpy="1.56466 -8.63678e-05 1.57138" /> -->
        <origin rpy="0.0 0.0 0.0" xyz="0.0 0.0 0.0" />
    </joint>
    <!--
    Base UR robot series xacro macro.

    NOTE: this is NOT a URDF. It cannot directly be loaded by consumers
    expecting a flattened '.urdf' file. See the top-level '.xacro' for that
    (but note: that .xacro must still be processed by the xacro command).

    For use in '.launch' files: use one of the 'load_urX.launch' convenience
    launch files.

    This file models the base kinematic chain of a UR robot, which then gets
    parameterised by various configuration files to convert it into a UR3(e),
    UR5(e), UR10(e) or UR16e.

    NOTE: the default kinematic parameters (ie: link lengths, frame locations,
    offets, etc) do not correspond to any particular robot. They are defaults
    only. There WILL be non-zero offsets between the Forward Kinematics results
    in TF (ie: robot_state_publisher) and the values reported by the Teach
    Pendant.

    For accurate (and robot-specific) transforms, the 'kinematics_parameters_file'
    parameter MUST point to a .yaml file containing the appropriate values for
    the targetted robot.

    If using the UniversalRobots/Universal_Robots_ROS_Driver, follow the steps
    described in the readme of that repository to extract the kinematic
    calibration from the controller and generate the required .yaml file.

    Main author of the migration to yaml configs: Ludovic Delval.

    Contributors to previous versions (in no particular order):

     - Felix Messmer
     - Kelsey Hawkins
     - Wim Meeussen
     - Shaun Edwards
     - Nadia Hammoudeh Garcia
     - Dave Hershberger
     - G. vd. Hoorn
     - Philip Long
     - Dave Coleman
     - Miguel Prada
     - Mathias Luedtke
     - Marcel Schnirring
     - Felix von Drigalski
     - Felix Exner
     - Jimmy Da Silva
     - Ajit Krisshna N L
     - Muhammad Asif Rana
  -->
    <!--
    NOTE: the macro defined in this file is NOT part of the public API of this
          package. Users CANNOT rely on this file being available, or stored in
          this location. Nor can they rely on the existence of the macro.
  -->
    <transmission name="right_shoulder_pan_trans">
        <type>transmission_interface/SimpleTransmission</type>
        <joint name="right_shoulder_pan_joint">
            <hardwareInterface>hardware_interface/PositionJointInterface</hardwareInterface>
        </joint>
        <actuator name="right_shoulder_pan_motor">
            <mechanicalReduction>1</mechanicalReduction>
        </actuator>
    </transmission>
    <transmission name="right_shoulder_lift_trans">
        <type>transmission_interface/SimpleTransmission</type>
        <joint name="right_shoulder_lift_joint">
            <hardwareInterface>hardware_interface/PositionJointInterface</hardwareInterface>
        </joint>
        <actuator name="right_shoulder_lift_motor">
            <mechanicalReduction>1</mechanicalReduction>
        </actuator>
    </transmission>
    <transmission name="right_elbow_trans">
        <type>transmission_interface/SimpleTransmission</type>
        <joint name="right_elbow_joint">
            <hardwareInterface>hardware_interface/PositionJointInterface</hardwareInterface>
        </joint>
        <actuator name="right_elbow_motor">
            <mechanicalReduction>1</mechanicalReduction>
        </actuator>
    </transmission>
    <transmission name="right_wrist_1_trans">
        <type>transmission_interface/SimpleTransmission</type>
        <joint name="right_wrist_1_joint">
            <hardwareInterface>hardware_interface/PositionJointInterface</hardwareInterface>
        </joint>
        <actuator name="right_wrist_1_motor">
            <mechanicalReduction>1</mechanicalReduction>
        </actuator>
    </transmission>
    <transmission name="right_wrist_2_trans">
        <type>transmission_interface/SimpleTransmission</type>
        <joint name="right_wrist_2_joint">
            <hardwareInterface>hardware_interface/PositionJointInterface</hardwareInterface>
        </joint>
        <actuator name="right_wrist_2_motor">
            <mechanicalReduction>1</mechanicalReduction>
        </actuator>
    </transmission>
    <transmission name="right_wrist_3_trans">
        <type>transmission_interface/SimpleTransmission</type>
        <joint name="right_wrist_3_joint">
            <hardwareInterface>hardware_interface/PositionJointInterface</hardwareInterface>
        </joint>
        <actuator name="right_wrist_3_motor">
            <mechanicalReduction>1</mechanicalReduction>
        </actuator>
    </transmission>
    <!-- links: main serial chain -->
    <link name="right_base_link" />
    <link name="right_base_link_inertia">
        <visual>
            <origin rpy="0 0 3.141592653589793" xyz="0 0 0" />
            <geometry>
                <mesh filename="../ur_description/meshes/ur5e/visual/base.dae" />
            </geometry>
            <material name="LightGrey">
                <color rgba="0.7 0.7 0.7 1.0" />
            </material>
        </visual>
        <collision>
            <origin rpy="0 0 3.141592653589793" xyz="0 0 0" />
            <geometry>
                <mesh filename="../ur_description/meshes/ur5e/collision/base.stl" />
            </geometry>
        </collision>
        <inertial>
            <mass value="4.0" />
            <origin rpy="0 0 0" xyz="0 0 0" />
            <inertia ixx="0.00443333156" ixy="0.0" ixz="0.0" iyy="0.00443333156" iyz="0.0"
                izz="0.0072" />
        </inertial>
    </link>
    <link name="right_shoulder_link">
        <visual>
            <origin rpy="0 0 3.141592653589793" xyz="0 0 0" />
            <geometry>
                <mesh filename="../ur_description/meshes/ur5e/visual/shoulder.dae" />
            </geometry>
            <material name="LightGrey">
                <color rgba="0.7 0.7 0.7 1.0" />
            </material>
        </visual>
        <collision>
            <origin rpy="0 0 3.141592653589793" xyz="0 0 0" />
            <geometry>
                <mesh filename="../ur_description/meshes/ur5e/collision/shoulder.stl" />
            </geometry>
        </collision>
        <inertial>
            <mass value="3.7" />
            <origin rpy="0 0 0" xyz="0 0 0" />
            <inertia ixx="0.010267495893" ixy="0.0" ixz="0.0" iyy="0.010267495893" iyz="0.0"
                izz="0.00666" />
        </inertial>
    </link>
    <link name="right_upper_arm_link">
        <visual>
            <origin rpy="1.5707963267948966 0 -1.5707963267948966" xyz="0 0 0.138" />
            <geometry>
                <mesh filename="../ur_description/meshes/ur5e/visual/upperarm.dae" />
            </geometry>
            <material name="LightGrey">
                <color rgba="0.7 0.7 0.7 1.0" />
            </material>
        </visual>
        <collision>
            <origin rpy="1.5707963267948966 0 -1.5707963267948966" xyz="0 0 0.138" />
            <geometry>
                <mesh filename="../ur_description/meshes/ur5e/collision/upperarm.stl" />
            </geometry>
        </collision>
        <inertial>
            <mass value="8.393" />
            <origin rpy="0 1.5707963267948966 0" xyz="-0.2125 0.0 0.138" />
            <inertia ixx="0.1338857818623325" ixy="0.0" ixz="0.0" iyy="0.1338857818623325" iyz="0.0"
                izz="0.0151074" />
        </inertial>
    </link>
    <link name="right_forearm_link">
        <visual>
            <origin rpy="1.5707963267948966 0 -1.5707963267948966" xyz="0 0 0.007" />
            <geometry>
                <mesh filename="../ur_description/meshes/ur5e/visual/forearm.dae" />
            </geometry>
            <material name="LightGrey">
                <color rgba="0.7 0.7 0.7 1.0" />
            </material>
        </visual>
        <collision>
            <origin rpy="1.5707963267948966 0 -1.5707963267948966" xyz="0 0 0.007" />
            <geometry>
                <mesh filename="../ur_description/meshes/ur5e/collision/forearm.stl" />
            </geometry>
        </collision>
        <inertial>
            <mass value="2.275" />
            <origin rpy="0 1.5707963267948966 0" xyz="-0.1961 0.0 0.007" />
            <inertia ixx="0.031209355099586295" ixy="0.0" ixz="0.0" iyy="0.031209355099586295"
                iyz="0.0" izz="0.004095" />
        </inertial>
    </link>
    <link name="right_wrist_1_link">
        <visual>
            <!-- TODO: Move this to a parameter -->
            <origin rpy="1.5707963267948966 0 0" xyz="0 0 -0.127" />
            <geometry>
                <mesh filename="../ur_description/meshes/ur5e/visual/wrist1.dae" />
            </geometry>
            <material name="LightGrey">
                <color rgba="0.7 0.7 0.7 1.0" />
            </material>
        </visual>
        <collision>
            <origin rpy="1.5707963267948966 0 0" xyz="0 0 -0.127" />
            <geometry>
                <mesh filename="../ur_description/meshes/ur5e/collision/wrist1.stl" />
            </geometry>
        </collision>
        <inertial>
            <mass value="1.219" />
            <origin rpy="0 0 0" xyz="0 0 0" />
            <inertia ixx="0.0025598989760400002" ixy="0.0" ixz="0.0" iyy="0.0025598989760400002"
                iyz="0.0" izz="0.0021942" />
        </inertial>
    </link>
    <link name="right_wrist_2_link">
        <visual>
            <origin rpy="0 0 0" xyz="0 0 -0.0997" />
            <geometry>
                <mesh filename="../ur_description/meshes/ur5e/visual/wrist2.dae" />
            </geometry>
            <material name="LightGrey">
                <color rgba="0.7 0.7 0.7 1.0" />
            </material>
        </visual>
        <collision>
            <origin rpy="0 0 0" xyz="0 0 -0.0997" />
            <geometry>
                <mesh filename="../ur_description/meshes/ur5e/collision/wrist2.stl" />
            </geometry>
        </collision>
        <inertial>
            <mass value="1.219" />
            <origin rpy="0 0 0" xyz="0 0 0" />
            <inertia ixx="0.0025598989760400002" ixy="0.0" ixz="0.0" iyy="0.0025598989760400002"
                iyz="0.0" izz="0.0021942" />
        </inertial>
    </link>
    <link name="right_wrist_3_link">
        <visual>
            <origin rpy="1.5707963267948966 0 0" xyz="0 0 -0.0989" />
            <geometry>
                <mesh filename="../ur_description/meshes/ur5e/visual/wrist3.dae" />
            </geometry>
            <material name="LightGrey">
                <color rgba="0.7 0.7 0.7 1.0" />
            </material>
        </visual>
        <collision>
            <origin rpy="1.5707963267948966 0 0" xyz="0 0 -0.0989" />
            <geometry>
                <mesh filename="../ur_description/meshes/ur5e/collision/wrist3.stl" />
            </geometry>
        </collision>
        <inertial>
            <mass value="0.1879" />
            <origin rpy="0 0 0" xyz="0.0 0.0 -0.0229" />
            <inertia ixx="9.890410052167731e-05" ixy="0.0" ixz="0.0" iyy="9.890410052167731e-05"
                iyz="0.0" izz="0.0001321171875" />
        </inertial>
    </link>
    <!-- joints: main serial chain -->
    <joint name="right_base_link-base_link_inertia" type="fixed">
        <parent link="right_base_link" />
        <child link="right_base_link_inertia" />
        <!-- 'base_link' is REP-103 aligned (so X+ forward), while the internal
           frames of the robot/controller have X+ pointing backwards.
           Use the joint between 'base_link' and 'base_link_inertia' (a dummy
           link/frame) to introduce the necessary rotation over Z (of pi rad).
      -->
        <origin rpy="0 0 3.141592653589793" xyz="0 0 0" />
    </joint>
    <joint name="right_shoulder_pan_joint" type="revolute">
        <parent link="right_base_link_inertia" />
        <child link="right_shoulder_link" />
        <origin rpy="0 0 0" xyz="0 0 0.1625" />
        <axis xyz="0 0 1" />
        <limit effort="150.0" lower="-6.283185307179586" upper="6.283185307179586"
            velocity="3.141592653589793" />
        <dynamics damping="0" friction="0" />
    </joint>
    <joint name="right_shoulder_lift_joint" type="revolute">
        <parent link="right_shoulder_link" />
        <child link="right_upper_arm_link" />
        <origin rpy="1.570796327 0 0" xyz="0 0 0" />
        <axis xyz="0 0 1" />
        <limit effort="150.0" lower="-6.283185307179586" upper="6.283185307179586"
            velocity="3.141592653589793" />
        <dynamics damping="0" friction="0" />
    </joint>
    <joint name="right_elbow_joint" type="revolute">
        <parent link="right_upper_arm_link" />
        <child link="right_forearm_link" />
        <origin rpy="0 0 0" xyz="-0.425 0 0" />
        <axis xyz="0 0 1" />
        <limit effort="150.0" lower="-3.141592653589793" upper="3.141592653589793"
            velocity="3.141592653589793" />
        <dynamics damping="0" friction="0" />
    </joint>
    <joint name="right_wrist_1_joint" type="revolute">
        <parent link="right_forearm_link" />
        <child link="right_wrist_1_link" />
        <origin rpy="0 0 0" xyz="-0.3922 0 0.1333" />
        <axis xyz="0 0 1" />
        <limit effort="28.0" lower="-6.283185307179586" upper="6.283185307179586"
            velocity="3.141592653589793" />
        <dynamics damping="0" friction="0" />
    </joint>
    <joint name="right_wrist_2_joint" type="revolute">
        <parent link="right_wrist_1_link" />
        <child link="right_wrist_2_link" />
        <origin rpy="1.570796327 0 0" xyz="0 -0.0997 -2.044881182297852e-11" />
        <axis xyz="0 0 1" />
        <limit effort="28.0" lower="-6.283185307179586" upper="6.283185307179586"
            velocity="3.141592653589793" />
        <dynamics damping="0" friction="0" />
    </joint>
    <joint name="right_wrist_3_joint" type="revolute">
        <parent link="right_wrist_2_link" />
        <child link="right_wrist_3_link" />
        <origin rpy="1.570796326589793 3.141592653589793 3.141592653589793"
            xyz="0 0.0996 -2.042830148012698e-11" />
        <axis xyz="0 0 1" />
        <limit effort="28.0" lower="-6.283185307179586" upper="6.283185307179586"
            velocity="3.141592653589793" />
        <dynamics damping="0" friction="0" />
    </joint>
    <!-- ROS-Industrial 'base' frame: base_link to UR 'Base' Coordinates transform -->
    <link name="right_base" />
    <joint name="right_base_link-base_fixed_joint" type="fixed">
        <!-- Note the rotation over Z of pi radians: as base_link is REP-103
           aligned (ie: has X+ forward, Y+ left and Z+ up), this is needed
           to correctly align 'base' with the 'Base' coordinate system of
           the UR controller.
      -->
        <origin rpy="0 0 3.141592653589793" xyz="0 0 0" />
        <parent link="right_base_link" />
        <child link="right_base" />
    </joint>
    <!-- ROS-Industrial 'flange' frame: attachment point for EEF models -->
    <link name="right_flange" />
    <joint name="right_wrist_3-flange" type="fixed">
        <parent link="right_wrist_3_link" />
        <child link="right_flange" />
        <origin rpy="0 -1.5707963267948966 -1.5707963267948966" xyz="0 0 0" />
    </joint>
    <!-- ROS-Industrial 'tool0' frame: all-zeros tool frame -->
    <link name="right_tool0" />
    <joint name="right_flange-tool0" type="fixed">
        <!-- default toolframe: X+ left, Y+ up, Z+ front -->
        <origin rpy="1.5707963267948966 0 1.5707963267948966" xyz="0 0 0" />
        <parent link="right_flange" />
        <child link="right_tool0" />
    </joint>
    <!--
    Base UR robot series xacro macro.

    NOTE: this is NOT a URDF. It cannot directly be loaded by consumers
    expecting a flattened '.urdf' file. See the top-level '.xacro' for that
    (but note: that .xacro must still be processed by the xacro command).

    For use in '.launch' files: use one of the 'load_urX.launch' convenience
    launch files.

    This file models the base kinematic chain of a UR robot, which then gets
    parameterised by various configuration files to convert it into a UR3(e),
    UR5(e), UR10(e) or UR16e.

    NOTE: the default kinematic parameters (ie: link lengths, frame locations,
    offets, etc) do not correspond to any particular robot. They are defaults
    only. There WILL be non-zero offsets between the Forward Kinematics results
    in TF (ie: robot_state_publisher) and the values reported by the Teach
    Pendant.

    For accurate (and robot-specific) transforms, the 'kinematics_parameters_file'
    parameter MUST point to a .yaml file containing the appropriate values for
    the targetted robot.

    If using the UniversalRobots/Universal_Robots_ROS_Driver, follow the steps
    described in the readme of that repository to extract the kinematic
    calibration from the controller and generate the required .yaml file.

    Main author of the migration to yaml configs: Ludovic Delval.

    Contributors to previous versions (in no particular order):

     - Felix Messmer
     - Kelsey Hawkins
     - Wim Meeussen
     - Shaun Edwards
     - Nadia Hammoudeh Garcia
     - Dave Hershberger
     - G. vd. Hoorn
     - Philip Long
     - Dave Coleman
     - Miguel Prada
     - Mathias Luedtke
     - Marcel Schnirring
     - Felix von Drigalski
     - Felix Exner
     - Jimmy Da Silva
     - Ajit Krisshna N L
     - Muhammad Asif Rana
  -->
    <!--
    NOTE: the macro defined in this file is NOT part of the public API of this
          package. Users CANNOT rely on this file being available, or stored in
          this location. Nor can they rely on the existence of the macro.
  -->
    <transmission name="left_shoulder_pan_trans">
        <type>transmission_interface/SimpleTransmission</type>
        <joint name="left_shoulder_pan_joint">
            <hardwareInterface>hardware_interface/PositionJointInterface</hardwareInterface>
        </joint>
        <actuator name="left_shoulder_pan_motor">
            <mechanicalReduction>1</mechanicalReduction>
        </actuator>
    </transmission>
    <transmission name="left_shoulder_lift_trans">
        <type>transmission_interface/SimpleTransmission</type>
        <joint name="left_shoulder_lift_joint">
            <hardwareInterface>hardware_interface/PositionJointInterface</hardwareInterface>
        </joint>
        <actuator name="left_shoulder_lift_motor">
            <mechanicalReduction>1</mechanicalReduction>
        </actuator>
    </transmission>
    <transmission name="left_elbow_trans">
        <type>transmission_interface/SimpleTransmission</type>
        <joint name="left_elbow_joint">
            <hardwareInterface>hardware_interface/PositionJointInterface</hardwareInterface>
        </joint>
        <actuator name="left_elbow_motor">
            <mechanicalReduction>1</mechanicalReduction>
        </actuator>
    </transmission>
    <transmission name="left_wrist_1_trans">
        <type>transmission_interface/SimpleTransmission</type>
        <joint name="left_wrist_1_joint">
            <hardwareInterface>hardware_interface/PositionJointInterface</hardwareInterface>
        </joint>
        <actuator name="left_wrist_1_motor">
            <mechanicalReduction>1</mechanicalReduction>
        </actuator>
    </transmission>
    <transmission name="left_wrist_2_trans">
        <type>transmission_interface/SimpleTransmission</type>
        <joint name="left_wrist_2_joint">
            <hardwareInterface>hardware_interface/PositionJointInterface</hardwareInterface>
        </joint>
        <actuator name="left_wrist_2_motor">
            <mechanicalReduction>1</mechanicalReduction>
        </actuator>
    </transmission>
    <transmission name="left_wrist_3_trans">
        <type>transmission_interface/SimpleTransmission</type>
        <joint name="left_wrist_3_joint">
            <hardwareInterface>hardware_interface/PositionJointInterface</hardwareInterface>
        </joint>
        <actuator name="left_wrist_3_motor">
            <mechanicalReduction>1</mechanicalReduction>
        </actuator>
    </transmission>
    <!-- links: main serial chain -->
    <link name="left_base_link" />
    <link name="left_base_link_inertia">
        <visual>
            <origin rpy="0 0 3.141592653589793" xyz="0 0 0" />
            <geometry>
                <mesh filename="../ur_description/meshes/ur5e/visual/base.dae" />
            </geometry>
            <material name="LightGrey">
                <color rgba="0.7 0.7 0.7 1.0" />
            </material>
        </visual>
        <collision>
            <origin rpy="0 0 3.141592653589793" xyz="0 0 0" />
            <geometry>
                <mesh filename="../ur_description/meshes/ur5e/collision/base.stl" />
            </geometry>
        </collision>
        <inertial>
            <mass value="4.0" />
            <origin rpy="0 0 0" xyz="0 0 0" />
            <inertia ixx="0.00443333156" ixy="0.0" ixz="0.0" iyy="0.00443333156" iyz="0.0"
                izz="0.0072" />
        </inertial>
    </link>
    <link name="left_shoulder_link">
        <visual>
            <origin rpy="0 0 3.141592653589793" xyz="0 0 0" />
            <geometry>
                <mesh filename="../ur_description/meshes/ur5e/visual/shoulder.dae" />
            </geometry>
            <material name="LightGrey">
                <color rgba="0.7 0.7 0.7 1.0" />
            </material>
        </visual>
        <collision>
            <origin rpy="0 0 3.141592653589793" xyz="0 0 0" />
            <geometry>
                <mesh filename="../ur_description/meshes/ur5e/collision/shoulder.stl" />
            </geometry>
        </collision>
        <inertial>
            <mass value="3.7" />
            <origin rpy="0 0 0" xyz="0 0 0" />
            <inertia ixx="0.010267495893" ixy="0.0" ixz="0.0" iyy="0.010267495893" iyz="0.0"
                izz="0.00666" />
        </inertial>
    </link>
    <link name="left_upper_arm_link">
        <visual>
            <origin rpy="1.5707963267948966 0 -1.5707963267948966" xyz="0 0 0.138" />
            <geometry>
                <mesh filename="../ur_description/meshes/ur5e/visual/upperarm.dae" />
            </geometry>
            <material name="LightGrey">
                <color rgba="0.7 0.7 0.7 1.0" />
            </material>
        </visual>
        <collision>
            <origin rpy="1.5707963267948966 0 -1.5707963267948966" xyz="0 0 0.138" />
            <geometry>
                <mesh filename="../ur_description/meshes/ur5e/collision/upperarm.stl" />
            </geometry>
        </collision>
        <inertial>
            <mass value="8.393" />
            <origin rpy="0 1.5707963267948966 0" xyz="-0.2125 0.0 0.138" />
            <inertia ixx="0.1338857818623325" ixy="0.0" ixz="0.0" iyy="0.1338857818623325" iyz="0.0"
                izz="0.0151074" />
        </inertial>
    </link>
    <link name="left_forearm_link">
        <visual>
            <origin rpy="1.5707963267948966 0 -1.5707963267948966" xyz="0 0 0.007" />
            <geometry>
                <mesh filename="../ur_description/meshes/ur5e/visual/forearm.dae" />
            </geometry>
            <material name="LightGrey">
                <color rgba="0.7 0.7 0.7 1.0" />
            </material>
        </visual>
        <collision>
            <origin rpy="1.5707963267948966 0 -1.5707963267948966" xyz="0 0 0.007" />
            <geometry>
                <mesh filename="../ur_description/meshes/ur5e/collision/forearm.stl" />
            </geometry>
        </collision>
        <inertial>
            <mass value="2.275" />
            <origin rpy="0 1.5707963267948966 0" xyz="-0.1961 0.0 0.007" />
            <inertia ixx="0.031209355099586295" ixy="0.0" ixz="0.0" iyy="0.031209355099586295"
                iyz="0.0" izz="0.004095" />
        </inertial>
    </link>
    <link name="left_wrist_1_link">
        <visual>
            <!-- TODO: Move this to a parameter -->
            <origin rpy="1.5707963267948966 0 0" xyz="0 0 -0.127" />
            <geometry>
                <mesh filename="../ur_description/meshes/ur5e/visual/wrist1.dae" />
            </geometry>
            <material name="LightGrey">
                <color rgba="0.7 0.7 0.7 1.0" />
            </material>
        </visual>
        <collision>
            <origin rpy="1.5707963267948966 0 0" xyz="0 0 -0.127" />
            <geometry>
                <mesh filename="../ur_description/meshes/ur5e/collision/wrist1.stl" />
            </geometry>
        </collision>
        <inertial>
            <mass value="1.219" />
            <origin rpy="0 0 0" xyz="0 0 0" />
            <inertia ixx="0.0025598989760400002" ixy="0.0" ixz="0.0" iyy="0.0025598989760400002"
                iyz="0.0" izz="0.0021942" />
        </inertial>
    </link>
    <link name="left_wrist_2_link">
        <visual>
            <origin rpy="0 0 0" xyz="0 0 -0.0997" />
            <geometry>
                <mesh filename="../ur_description/meshes/ur5e/visual/wrist2.dae" />
            </geometry>
            <material name="LightGrey">
                <color rgba="0.7 0.7 0.7 1.0" />
            </material>
        </visual>
        <collision>
            <origin rpy="0 0 0" xyz="0 0 -0.0997" />
            <geometry>
                <mesh filename="../ur_description/meshes/ur5e/collision/wrist2.stl" />
            </geometry>
        </collision>
        <inertial>
            <mass value="1.219" />
            <origin rpy="0 0 0" xyz="0 0 0" />
            <inertia ixx="0.0025598989760400002" ixy="0.0" ixz="0.0" iyy="0.0025598989760400002"
                iyz="0.0" izz="0.0021942" />
        </inertial>
    </link>
    <link name="left_wrist_3_link">
        <visual>
            <origin rpy="1.5707963267948966 0 0" xyz="0 0 -0.0989" />
            <geometry>
                <mesh filename="../ur_description/meshes/ur5e/visual/wrist3.dae" />
            </geometry>
            <material name="LightGrey">
                <color rgba="0.7 0.7 0.7 1.0" />
            </material>
        </visual>
        <collision>
            <origin rpy="1.5707963267948966 0 0" xyz="0 0 -0.0989" />
            <geometry>
                <mesh filename="../ur_description/meshes/ur5e/collision/wrist3.stl" />
            </geometry>
        </collision>
        <inertial>
            <mass value="0.1879" />
            <origin rpy="0 0 0" xyz="0.0 0.0 -0.0229" />
            <inertia ixx="9.890410052167731e-05" ixy="0.0" ixz="0.0" iyy="9.890410052167731e-05"
                iyz="0.0" izz="0.0001321171875" />
        </inertial>
    </link>
    <!-- joints: main serial chain -->
    <joint name="left_base_link-base_link_inertia" type="fixed">
        <parent link="left_base_link" />
        <child link="left_base_link_inertia" />
        <!-- 'base_link' is REP-103 aligned (so X+ forward), while the internal
           frames of the robot/controller have X+ pointing backwards.
           Use the joint between 'base_link' and 'base_link_inertia' (a dummy
           link/frame) to introduce the necessary rotation over Z (of pi rad).
      -->
        <origin rpy="0 0 3.141592653589793" xyz="0 0 0" />
    </joint>
    <joint name="left_shoulder_pan_joint" type="revolute">
        <parent link="left_base_link_inertia" />
        <child link="left_shoulder_link" />
        <origin rpy="0 0 0" xyz="0 0 0.1625" />
        <axis xyz="0 0 1" />
        <limit effort="150.0" lower="-6.283185307179586" upper="6.283185307179586"
            velocity="3.141592653589793" />
        <dynamics damping="0" friction="0" />
    </joint>
    <joint name="left_shoulder_lift_joint" type="revolute">
        <parent link="left_shoulder_link" />
        <child link="left_upper_arm_link" />
        <origin rpy="1.570796327 0 0" xyz="0 0 0" />
        <axis xyz="0 0 1" />
        <limit effort="150.0" lower="-6.283185307179586" upper="6.283185307179586"
            velocity="3.141592653589793" />
        <dynamics damping="0" friction="0" />
    </joint>
    <joint name="left_elbow_joint" type="revolute">
        <parent link="left_upper_arm_link" />
        <child link="left_forearm_link" />
        <origin rpy="0 0 0" xyz="-0.425 0 0" />
        <axis xyz="0 0 1" />
        <limit effort="150.0" lower="-3.141592653589793" upper="3.141592653589793"
            velocity="3.141592653589793" />
        <dynamics damping="0" friction="0" />
    </joint>
    <joint name="left_wrist_1_joint" type="revolute">
        <parent link="left_forearm_link" />
        <child link="left_wrist_1_link" />
        <origin rpy="0 0 0" xyz="-0.3922 0 0.1333" />
        <axis xyz="0 0 1" />
        <limit effort="28.0" lower="-6.283185307179586" upper="6.283185307179586"
            velocity="3.141592653589793" />
        <dynamics damping="0" friction="0" />
    </joint>
    <joint name="left_wrist_2_joint" type="revolute">
        <parent link="left_wrist_1_link" />
        <child link="left_wrist_2_link" />
        <origin rpy="1.570796327 0 0" xyz="0 -0.0997 -2.044881182297852e-11" />
        <axis xyz="0 0 1" />
        <limit effort="28.0" lower="-6.283185307179586" upper="6.283185307179586"
            velocity="3.141592653589793" />
        <dynamics damping="0" friction="0" />
    </joint>
    <joint name="left_wrist_3_joint" type="revolute">
        <parent link="left_wrist_2_link" />
        <child link="left_wrist_3_link" />
        <origin rpy="1.570796326589793 3.141592653589793 3.141592653589793"
            xyz="0 0.0996 -2.042830148012698e-11" />
        <axis xyz="0 0 1" />
        <limit effort="28.0" lower="-6.283185307179586" upper="6.283185307179586"
            velocity="3.141592653589793" />
        <dynamics damping="0" friction="0" />
    </joint>
    <!-- ROS-Industrial 'base' frame: base_link to UR 'Base' Coordinates transform -->
    <link name="left_base" />
    <joint name="left_base_link-base_fixed_joint" type="fixed">
        <!-- Note the rotation over Z of pi radians: as base_link is REP-103
           aligned (ie: has X+ forward, Y+ left and Z+ up), this is needed
           to correctly align 'base' with the 'Base' coordinate system of
           the UR controller.
      -->
        <origin rpy="0 0 3.141592653589793" xyz="0 0 0" />
        <parent link="left_base_link" />
        <child link="left_base" />
    </joint>
    <!-- ROS-Industrial 'flange' frame: attachment point for EEF models -->
    <link name="left_flange" />
    <joint name="left_wrist_3-flange" type="fixed">
        <parent link="left_wrist_3_link" />
        <child link="left_flange" />
        <origin rpy="0 -1.5707963267948966 -1.5707963267948966" xyz="0 0 0" />
    </joint>
    <!-- ROS-Industrial 'tool0' frame: all-zeros tool frame -->
    <link name="left_tool0" />
    <joint name="left_flange-tool0" type="fixed">
        <!-- default toolframe: X+ left, Y+ up, Z+ front -->
        <origin rpy="1.5707963267948966 0 1.5707963267948966" xyz="0 0 0" />
        <parent link="left_flange" />
        <child link="left_tool0" />
    </joint>
    <joint name="right_robot_to_base" type="fixed">
        <parent link="base" />
        <child link="right_base_link" />
        <!-- <origin xyz="0.432 0.508 0.660" rpy="1.5708 1.5708 0.0"/> -->
        <origin rpy="2.208204442577555 1.5612544500525112 0.6223073791846901"
            xyz="0.31151492 0.50284408 0.64784629" />
    </joint>
    <joint name="left_robot_to_base" type="fixed">
        <parent link="base" />
        <child link="left_base_link" />
        <origin rpy="1.5708 -1.5708 0.0" xyz="-0.432 0.508 0.660" />
    </joint>
    <!-- Robotiq Coupler -->
    <!--  + Height added by the coupler: 8mm -->
    <!--  + Reference frame: at the middle (4mm) -->
    <link name="right_robotiq_coupler">
        <visual>
            <geometry>
                <mesh filename="../robotiq_description/meshes/robotiq_85_coupler.stl" />
            </geometry>
            <!-- <material name="flat_black"/> -->
            <material name="">
                <color rgba="0.1 0.1 0.1 1" />
            </material>
        </visual>
        <collision>
            <geometry>
                <mesh filename="../robotiq_description/meshes/robotiq_85_coupler.stl" />
            </geometry>
        </collision>
        <inertial>
            <origin rpy="0 0 0" xyz="2.073e-05   1.45286e-03  -1.1049e-03" />
            <mass value="0.168" />
            <inertia ixx="6.69695624e-05" ixy="5.21511788e-09" ixz="-2.74383009e-08"
                iyy="7.85088161e-05" iyz="5.41105193e-07" izz="1.41819717e-04" />
        </inertial>
    </link>
    <joint name="right_robotiq_coupler_joint" type="fixed">
        <origin rpy="0 0 -1.5707963267948966" xyz="0 0 0.004" />
        <parent link="right_tool0" />
        <child link="right_robotiq_coupler" />
    </joint>
    <joint name="right_robotiq_85_base_joint" type="fixed">
        <parent link="right_robotiq_coupler" />
        <child link="right_robotiq_85_base_link" />
        <origin rpy="0 -1.5707963267948966 3.141592653589793" xyz="0 0 0.004" />
    </joint>
    <link name="right_robotiq_85_base_link">
        <visual>
            <geometry>
                <mesh filename="../robotiq_description/meshes/visual/robotiq_85_base_link.dae" />
            </geometry>
            <material name="">
                <color rgba="0.1 0.1 0.1 1" />
            </material>
        </visual>
        <collision>
            <geometry>
                <mesh filename="../robotiq_description/meshes/collision/robotiq_85_base_link.stl" />
            </geometry>
        </collision>
        <inertial>
            <mass value="0.636951" />
            <origin xyz="0.0 0.0 0.0" />
            <inertia ixx="0.000380" ixy="0.000000" ixz="0.000000" iyx="0.000000" iyy="0.001110"
                iyz="0.000000" izx="0.000000" izy="0.000000" izz="0.001171" />
        </inertial>
    </link>
    <joint name="right_robotiq_85_left_knuckle_joint" type="revolute">
        <parent link="right_robotiq_85_base_link" />
        <child link="right_robotiq_85_left_knuckle_link" />
        <axis xyz="0 0 1" />
        <origin rpy="3.141592653589793 0.0 0.0" xyz="0.05490451627 0.03060114443 0.0" />
        <limit effort="1000" lower="0.0" upper="0.80285" velocity="0.5" />
    </joint>
    <joint name="right_robotiq_85_right_knuckle_joint" type="continuous">
        <parent link="right_robotiq_85_base_link" />
        <child link="right_robotiq_85_right_knuckle_link" />
        <axis xyz="0 0 1" />
        <origin rpy="0.0 0.0 0.0" xyz="0.05490451627 -0.03060114443 0.0" />
        <limit effort="1000" lower="-3.14" upper="3.14" velocity="100.0" />
        <mimic joint="right_robotiq_85_left_knuckle_joint" />
    </joint>
    <link name="right_robotiq_85_left_knuckle_link">
        <visual>
            <geometry>
                <mesh filename="../robotiq_description/meshes/visual/robotiq_85_knuckle_link.dae" />
            </geometry>
            <material name="">
                <color rgba="0.1 0.1 0.1 1" />
            </material>
        </visual>
        <collision>
            <geometry>
                <mesh filename="../robotiq_description/meshes/collision/robotiq_85_knuckle_link.stl" />
            </geometry>
        </collision>
        <inertial>
            <mass value="0.018491" />
            <origin xyz="0.0 0.0 0.0" />
            <inertia ixx="0.000009" ixy="-0.000001" ixz="0.000000" iyx="-0.000001" iyy="0.000001"
                iyz="0.000000" izx="0.000000" izy="0.000000" izz="0.000010" />
        </inertial>
    </link>
    <link name="right_robotiq_85_right_knuckle_link">
        <visual>
            <geometry>
                <mesh filename="../robotiq_description/meshes/visual/robotiq_85_knuckle_link.dae" />
            </geometry>
            <material name="">
                <color rgba="0.1 0.1 0.1 1" />
            </material>
        </visual>
        <collision>
            <geometry>
                <mesh filename="../robotiq_description/meshes/collision/robotiq_85_knuckle_link.stl" />
            </geometry>
        </collision>
        <inertial>
            <mass value="0.018491" />
            <origin xyz="0.0 0.0 0.0" />
            <inertia ixx="0.000009" ixy="-0.000001" ixz="0.000000" iyx="-0.000001" iyy="0.000001"
                iyz="0.000000" izx="0.000000" izy="0.000000" izz="0.000010" />
        </inertial>
    </link>
    <joint name="right_robotiq_85_left_finger_joint" type="fixed">
        <parent link="right_robotiq_85_left_knuckle_link" />
        <child link="right_robotiq_85_left_finger_link" />
        <origin rpy="0 0 0" xyz="-0.00408552455 -0.03148604435 0.0" />
    </joint>
    <joint name="right_robotiq_85_right_finger_joint" type="fixed">
        <parent link="right_robotiq_85_right_knuckle_link" />
        <child link="right_robotiq_85_right_finger_link" />
        <origin rpy="0 0 0" xyz="-0.00408552455 -0.03148604435 0.0" />
    </joint>
    <link name="right_robotiq_85_left_finger_link">
        <visual>
            <geometry>
                <mesh filename="../robotiq_description/meshes/visual/robotiq_85_finger_link.dae" />
            </geometry>
            <material name="">
                <color rgba="0.1 0.1 0.1 1" />
            </material>
        </visual>
        <collision>
            <geometry>
                <mesh filename="../robotiq_description/meshes/collision/robotiq_85_finger_link.stl" />
            </geometry>
        </collision>
        <inertial>
            <mass value="0.027309" />
            <origin xyz="0.0 0.0 0.0" />
            <inertia ixx="0.000003" ixy="-0.000002" ixz="0.000000" iyx="-0.000002" iyy="0.000021"
                iyz="0.000000" izx="0.000000" izy="0.000000" izz="0.000020" />
        </inertial>
    </link>
    <link name="right_robotiq_85_right_finger_link">
        <visual>
            <geometry>
                <mesh filename="../robotiq_description/meshes/visual/robotiq_85_finger_link.dae" />
            </geometry>
            <material name="">
                <color rgba="0.1 0.1 0.1 1" />
            </material>
        </visual>
        <collision>
            <geometry>
                <mesh filename="../robotiq_description/meshes/collision/robotiq_85_finger_link.stl" />
            </geometry>
        </collision>
        <inertial>
            <mass value="0.027309" />
            <origin xyz="0.0 0.0 0.0" />
            <inertia ixx="0.000003" ixy="-0.000002" ixz="0.000000" iyx="-0.000002" iyy="0.000021"
                iyz="0.000000" izx="0.000000" izy="0.000000" izz="0.000020" />
        </inertial>
    </link>
    <joint name="right_robotiq_85_left_inner_knuckle_joint" type="continuous">
        <parent link="right_robotiq_85_base_link" />
        <child link="right_robotiq_85_left_inner_knuckle_link" />
        <axis xyz="0 0 1" />
        <origin rpy="3.141592653589793 0.0 0.0" xyz="0.06142 0.0127 0" />
        <limit effort="0.1" lower="-3.14" upper="3.14" velocity="100.0" />
        <mimic joint="right_robotiq_85_left_knuckle_joint" offset="0" />
    </joint>
    <joint name="right_robotiq_85_right_inner_knuckle_joint" type="continuous">
        <parent link="right_robotiq_85_base_link" />
        <child link="right_robotiq_85_right_inner_knuckle_link" />
        <axis xyz="0 0 1" />
        <origin rpy="0 0 0" xyz="0.06142 -0.0127 0" />
        <limit effort="0.1" lower="-3.14" upper="3.14" velocity="100.0" />
        <mimic joint="right_robotiq_85_left_knuckle_joint" offset="0" />
    </joint>
    <link name="right_robotiq_85_left_inner_knuckle_link">
        <visual>
            <geometry>
                <mesh
                    filename="../robotiq_description/meshes/visual/robotiq_85_inner_knuckle_link.dae" />
            </geometry>
            <material name="">
                <color rgba="0.1 0.1 0.1 1" />
            </material>
        </visual>
        <collision>
            <geometry>
                <mesh
                    filename="../robotiq_description/meshes/collision/robotiq_85_inner_knuckle_link.stl" />
            </geometry>
        </collision>
        <inertial>
            <mass value="0.029951" />
            <origin xyz="0.0 0.0 0.0" />
            <inertia ixx="0.000039" ixy="0.000000" ixz="0.000000" iyx="0.000000" iyy="0.000005"
                iyz="0.000000" izx="0.000000" izy="0.000000" izz="0.000035" />
        </inertial>
    </link>
    <link name="right_robotiq_85_right_inner_knuckle_link">
        <visual>
            <geometry>
                <mesh
                    filename="../robotiq_description/meshes/visual/robotiq_85_inner_knuckle_link.dae" />
            </geometry>
            <material name="">
                <color rgba="0.1 0.1 0.1 1" />
            </material>
        </visual>
        <collision>
            <geometry>
                <mesh
                    filename="../robotiq_description/meshes/collision/robotiq_85_inner_knuckle_link.stl" />
            </geometry>
        </collision>
        <inertial>
            <mass value="0.029951" />
            <origin xyz="0.0 0.0 0.0" />
            <inertia ixx="0.000039" ixy="0.000000" ixz="0.000000" iyx="0.000000" iyy="0.000005"
                iyz="0.000000" izx="0.000000" izy="0.000000" izz="0.000035" />
        </inertial>
    </link>
    <joint name="right_robotiq_85_left_finger_tip_joint" type="continuous">
        <parent link="right_robotiq_85_left_inner_knuckle_link" />
        <child link="right_robotiq_85_left_finger_tip_link" />
        <axis xyz="0 0 1" />
        <origin rpy="0.0 0.0 0.0" xyz="0.04303959807 -0.03759940821 0.0" />
        <limit effort="0.1" lower="-3.14" upper="3.14" velocity="100.0" />
        <mimic joint="right_robotiq_85_left_knuckle_joint" multiplier="-1" />
    </joint>
    <joint name="right_robotiq_85_right_finger_tip_joint" type="continuous">
        <parent link="right_robotiq_85_right_inner_knuckle_link" />
        <child link="right_robotiq_85_right_finger_tip_link" />
        <axis xyz="0 0 1" />
        <origin rpy="0.0 0.0 0.0" xyz="0.04303959807 -0.03759940821  0.0" />
        <limit effort="0.1" lower="-3.14" upper="3.14" velocity="100.0" />
        <mimic joint="right_robotiq_85_left_knuckle_joint" multiplier="-1" />
    </joint>
    <link name="right_robotiq_85_left_finger_tip_link">
        <visual>
            <geometry>
                <mesh filename="../robotiq_description/meshes/visual/robotiq_85_finger_tip_link.dae" />
            </geometry>
            <material name="">
                <color rgba="0.1 0.1 0.1 1" />
            </material>
        </visual>
        <collision>
            <geometry>
                <mesh
                    filename="../robotiq_description/meshes/collision/robotiq_85_finger_tip_link.stl" />
            </geometry>
        </collision>
        <inertial>
            <mass value="0.019555" />
            <origin xyz="0.0 0.0 0.0" />
            <inertia ixx="0.000002" ixy="0.000000" ixz="0.000000" iyx="0.000000" iyy="0.000005"
                iyz="0.000000" izx="0.000000" izy="0.000000" izz="0.000006" />
        </inertial>
    </link>
    <link name="right_robotiq_85_right_finger_tip_link">
        <visual>
            <geometry>
                <mesh filename="../robotiq_description/meshes/visual/robotiq_85_finger_tip_link.dae" />
            </geometry>
            <material name="">
                <color rgba="0.1 0.1 0.1 1" />
            </material>
        </visual>
        <collision>
            <geometry>
                <mesh
                    filename="../robotiq_description/meshes/collision/robotiq_85_finger_tip_link.stl" />
            </geometry>
        </collision>
        <inertial>
            <mass value="0.019555" />
            <origin xyz="0.0 0.0 0.0" />
            <inertia ixx="0.000002" ixy="0.000000" ixz="0.000000" iyx="0.000000" iyy="0.000005"
                iyz="0.000000" izx="0.000000" izy="0.000000" izz="0.000006" />
        </inertial>
    </link>
    <!-- Improve grasping physics -->
    <gazebo reference="right_robotiq_85_left_finger_tip_link">
        <kp>1000000.0</kp>
        <kd>1.0</kd>
        <mu1>1.0</mu1>
        <mu2>1.0</mu2>
        <minDepth>0.001</minDepth>
    </gazebo>
    <gazebo reference="right_robotiq_85_right_finger_tip_link">
        <kp>1000000.0</kp>
        <kd>1.0</kd>
        <mu1>1.0</mu1>
        <mu2>1.0</mu2>
        <minDepth>0.001</minDepth>
    </gazebo>
    <transmission name="right_robotiq_85_left_knuckle_trans">
        <type>transmission_interface/SimpleTransmission</type>
        <joint name="right_robotiq_85_left_knuckle_joint">
            <hardwareInterface>hardware_interface/EffortJointInterface</hardwareInterface>
            <!-- <hardwareInterface>EffortJointInterface</hardwareInterface> -->
        </joint>
        <actuator name="right_robotiq_85_left_knuckle_motor">
            <mechanicalReduction>1</mechanicalReduction>
            <hardwareInterface>hardware_interface/EffortJointInterface</hardwareInterface>
            <!-- <hardwareInterface>EfforJointInterface</hardwareInterface> -->
        </actuator>
    </transmission>
    <!-- Mimic joints -->
    <gazebo>
        <plugin filename="libgazebo_mimic_joint_plugin.so" name="right_mimic_robotiq_85_1">
            <joint>right_robotiq_85_left_knuckle_joint</joint>
            <mimicJoint>right_robotiq_85_right_knuckle_joint</mimicJoint>
        </plugin>
        <plugin filename="libgazebo_mimic_joint_plugin.so" name="right_mimic_robotiq_85_2">
            <joint>right_robotiq_85_left_knuckle_joint</joint>
            <mimicJoint>right_robotiq_85_left_inner_knuckle_joint</mimicJoint>
        </plugin>
        <plugin filename="libgazebo_mimic_joint_plugin.so" name="right_mimic_robotiq_85_3">
            <joint>right_robotiq_85_left_knuckle_joint</joint>
            <mimicJoint>right_robotiq_85_right_inner_knuckle_joint</mimicJoint>
        </plugin>
        <plugin filename="libgazebo_mimic_joint_plugin.so" name="right_mimic_robotiq_85_4">
            <joint>right_robotiq_85_left_knuckle_joint</joint>
            <mimicJoint>right_robotiq_85_left_finger_tip_joint</mimicJoint>
            <multiplier>-1.0</multiplier>
            <offset>0.0</offset>
        </plugin>
        <plugin filename="libgazebo_mimic_joint_plugin.so" name="right_mimic_robotiq_85_5">
            <joint>right_robotiq_85_left_knuckle_joint</joint>
            <mimicJoint>right_robotiq_85_right_finger_tip_joint</mimicJoint>
            <multiplier>-1.0</multiplier>
            <offset>0.0</offset>
        </plugin>
    </gazebo>
    <!-- Robotiq Coupler -->
    <!--  + Height added by the coupler: 8mm -->
    <!--  + Reference frame: at the middle (4mm) -->
    <link name="left_robotiq_coupler">
        <visual>
            <geometry>
                <mesh filename="../robotiq_description/meshes/robotiq_85_coupler.stl" />
            </geometry>
            <!-- <material name="flat_black"/> -->
        </visual>
        <collision>
            <geometry>
                <mesh filename="../robotiq_description/meshes/robotiq_85_coupler.stl" />
            </geometry>
        </collision>
        <inertial>
            <origin rpy="0 0 0" xyz="2.073e-05   1.45286e-03  -1.1049e-03" />
            <mass value="0.168" />
            <inertia ixx="6.69695624e-05" ixy="5.21511788e-09" ixz="-2.74383009e-08"
                iyy="7.85088161e-05" iyz="5.41105193e-07" izz="1.41819717e-04" />
        </inertial>
    </link>
    <joint name="left_robotiq_coupler_joint" type="fixed">
        <origin rpy="0 0 -1.5707963267948966" xyz="0 0 0.004" />
        <parent link="left_tool0" />
        <child link="left_robotiq_coupler" />
    </joint>
    <joint name="left_robotiq_85_base_joint" type="fixed">
        <parent link="left_robotiq_coupler" />
        <child link="left_robotiq_85_base_link" />
        <origin rpy="0 -1.5707963267948966 3.141592653589793" xyz="0 0 0.004" />
    </joint>
    <link name="left_robotiq_85_base_link">
        <visual>
            <geometry>
                <mesh filename="../robotiq_description/meshes/visual/robotiq_85_base_link.dae" />
            </geometry>
        </visual>
        <collision>
            <geometry>
                <mesh filename="../robotiq_description/meshes/collision/robotiq_85_base_link.stl" />
            </geometry>
        </collision>
        <inertial>
            <mass value="0.636951" />
            <origin xyz="0.0 0.0 0.0" />
            <inertia ixx="0.000380" ixy="0.000000" ixz="0.000000" iyx="0.000000" iyy="0.001110"
                iyz="0.000000" izx="0.000000" izy="0.000000" izz="0.001171" />
        </inertial>
    </link>
    <joint name="left_robotiq_85_left_knuckle_joint" type="revolute">
        <parent link="left_robotiq_85_base_link" />
        <child link="left_robotiq_85_left_knuckle_link" />
        <axis xyz="0 0 1" />
        <origin rpy="3.141592653589793 0.0 0.0" xyz="0.05490451627 0.03060114443 0.0" />
        <limit effort="1000" lower="0.0" upper="0.80285" velocity="0.5" />
    </joint>
    <joint name="left_robotiq_85_right_knuckle_joint" type="continuous">
        <parent link="left_robotiq_85_base_link" />
        <child link="left_robotiq_85_right_knuckle_link" />
        <axis xyz="0 0 1" />
        <origin rpy="0.0 0.0 0.0" xyz="0.05490451627 -0.03060114443 0.0" />
        <limit effort="1000" lower="-3.14" upper="3.14" velocity="100.0" />
        <mimic joint="left_robotiq_85_left_knuckle_joint" />
    </joint>
    <link name="left_robotiq_85_left_knuckle_link">
        <visual>
            <geometry>
                <mesh filename="../robotiq_description/meshes/visual/robotiq_85_knuckle_link.dae" />
            </geometry>
        </visual>
        <collision>
            <geometry>
                <mesh filename="../robotiq_description/meshes/collision/robotiq_85_knuckle_link.stl" />
            </geometry>
        </collision>
        <inertial>
            <mass value="0.018491" />
            <origin xyz="0.0 0.0 0.0" />
            <inertia ixx="0.000009" ixy="-0.000001" ixz="0.000000" iyx="-0.000001" iyy="0.000001"
                iyz="0.000000" izx="0.000000" izy="0.000000" izz="0.000010" />
        </inertial>
    </link>
    <link name="left_robotiq_85_right_knuckle_link">
        <visual>
            <geometry>
                <mesh filename="../robotiq_description/meshes/visual/robotiq_85_knuckle_link.dae" />
            </geometry>
        </visual>
        <collision>
            <geometry>
                <mesh filename="../robotiq_description/meshes/collision/robotiq_85_knuckle_link.stl" />
            </geometry>
        </collision>
        <inertial>
            <mass value="0.018491" />
            <origin xyz="0.0 0.0 0.0" />
            <inertia ixx="0.000009" ixy="-0.000001" ixz="0.000000" iyx="-0.000001" iyy="0.000001"
                iyz="0.000000" izx="0.000000" izy="0.000000" izz="0.000010" />
        </inertial>
    </link>
    <joint name="left_robotiq_85_left_finger_joint" type="fixed">
        <parent link="left_robotiq_85_left_knuckle_link" />
        <child link="left_robotiq_85_left_finger_link" />
        <origin rpy="0 0 0" xyz="-0.00408552455 -0.03148604435 0.0" />
    </joint>
    <joint name="left_robotiq_85_right_finger_joint" type="fixed">
        <parent link="left_robotiq_85_right_knuckle_link" />
        <child link="left_robotiq_85_right_finger_link" />
        <origin rpy="0 0 0" xyz="-0.00408552455 -0.03148604435 0.0" />
    </joint>
    <link name="left_robotiq_85_left_finger_link">
        <visual>
            <geometry>
                <mesh filename="../robotiq_description/meshes/visual/robotiq_85_finger_link.dae" />
            </geometry>
        </visual>
        <collision>
            <geometry>
                <mesh filename="../robotiq_description/meshes/collision/robotiq_85_finger_link.stl" />
            </geometry>
        </collision>
        <inertial>
            <mass value="0.027309" />
            <origin xyz="0.0 0.0 0.0" />
            <inertia ixx="0.000003" ixy="-0.000002" ixz="0.000000" iyx="-0.000002" iyy="0.000021"
                iyz="0.000000" izx="0.000000" izy="0.000000" izz="0.000020" />
        </inertial>
    </link>
    <link name="left_robotiq_85_right_finger_link">
        <visual>
            <geometry>
                <mesh filename="../robotiq_description/meshes/visual/robotiq_85_finger_link.dae" />
            </geometry>
        </visual>
        <collision>
            <geometry>
                <mesh filename="../robotiq_description/meshes/collision/robotiq_85_finger_link.stl" />
            </geometry>
        </collision>
        <inertial>
            <mass value="0.027309" />
            <origin xyz="0.0 0.0 0.0" />
            <inertia ixx="0.000003" ixy="-0.000002" ixz="0.000000" iyx="-0.000002" iyy="0.000021"
                iyz="0.000000" izx="0.000000" izy="0.000000" izz="0.000020" />
        </inertial>
    </link>
    <joint name="left_robotiq_85_left_inner_knuckle_joint" type="continuous">
        <parent link="left_robotiq_85_base_link" />
        <child link="left_robotiq_85_left_inner_knuckle_link" />
        <axis xyz="0 0 1" />
        <origin rpy="3.141592653589793 0.0 0.0" xyz="0.06142 0.0127 0" />
        <limit effort="0.1" lower="-3.14" upper="3.14" velocity="100.0" />
        <mimic joint="left_robotiq_85_left_knuckle_joint" offset="0" />
    </joint>
    <joint name="left_robotiq_85_right_inner_knuckle_joint" type="continuous">
        <parent link="left_robotiq_85_base_link" />
        <child link="left_robotiq_85_right_inner_knuckle_link" />
        <axis xyz="0 0 1" />
        <origin rpy="0 0 0" xyz="0.06142 -0.0127 0" />
        <limit effort="0.1" lower="-3.14" upper="3.14" velocity="100.0" />
        <mimic joint="left_robotiq_85_left_knuckle_joint" offset="0" />
    </joint>
    <link name="left_robotiq_85_left_inner_knuckle_link">
        <visual>
            <geometry>
                <mesh
                    filename="../robotiq_description/meshes/visual/robotiq_85_inner_knuckle_link.dae" />
            </geometry>
        </visual>
        <collision>
            <geometry>
                <mesh
                    filename="../robotiq_description/meshes/collision/robotiq_85_inner_knuckle_link.stl" />
            </geometry>
        </collision>
        <inertial>
            <mass value="0.029951" />
            <origin xyz="0.0 0.0 0.0" />
            <inertia ixx="0.000039" ixy="0.000000" ixz="0.000000" iyx="0.000000" iyy="0.000005"
                iyz="0.000000" izx="0.000000" izy="0.000000" izz="0.000035" />
        </inertial>
    </link>
    <link name="left_robotiq_85_right_inner_knuckle_link">
        <visual>
            <geometry>
                <mesh
                    filename="../robotiq_description/meshes/visual/robotiq_85_inner_knuckle_link.dae" />
            </geometry>
        </visual>
        <collision>
            <geometry>
                <mesh
                    filename="../robotiq_description/meshes/collision/robotiq_85_inner_knuckle_link.stl" />
            </geometry>
        </collision>
        <inertial>
            <mass value="0.029951" />
            <origin xyz="0.0 0.0 0.0" />
            <inertia ixx="0.000039" ixy="0.000000" ixz="0.000000" iyx="0.000000" iyy="0.000005"
                iyz="0.000000" izx="0.000000" izy="0.000000" izz="0.000035" />
        </inertial>
    </link>
    <joint name="left_robotiq_85_left_finger_tip_joint" type="continuous">
        <parent link="left_robotiq_85_left_inner_knuckle_link" />
        <child link="left_robotiq_85_left_finger_tip_link" />
        <axis xyz="0 0 1" />
        <origin rpy="0.0 0.0 0.0" xyz="0.04303959807 -0.03759940821 0.0" />
        <limit effort="0.1" lower="-3.14" upper="3.14" velocity="100.0" />
        <mimic joint="left_robotiq_85_left_knuckle_joint" multiplier="-1" />
    </joint>
    <joint name="left_robotiq_85_right_finger_tip_joint" type="continuous">
        <parent link="left_robotiq_85_right_inner_knuckle_link" />
        <child link="left_robotiq_85_right_finger_tip_link" />
        <axis xyz="0 0 1" />
        <origin rpy="0.0 0.0 0.0" xyz="0.04303959807 -0.03759940821  0.0" />
        <limit effort="0.1" lower="-3.14" upper="3.14" velocity="100.0" />
        <mimic joint="left_robotiq_85_left_knuckle_joint" multiplier="-1" />
    </joint>
    <link name="left_robotiq_85_left_finger_tip_link">
        <visual>
            <geometry>
                <mesh filename="../robotiq_description/meshes/visual/robotiq_85_finger_tip_link.dae" />
            </geometry>
        </visual>
        <collision>
            <geometry>
                <mesh
                    filename="../robotiq_description/meshes/collision/robotiq_85_finger_tip_link.stl" />
            </geometry>
        </collision>
        <inertial>
            <mass value="0.019555" />
            <origin xyz="0.0 0.0 0.0" />
            <inertia ixx="0.000002" ixy="0.000000" ixz="0.000000" iyx="0.000000" iyy="0.000005"
                iyz="0.000000" izx="0.000000" izy="0.000000" izz="0.000006" />
        </inertial>
    </link>
    <link name="left_robotiq_85_right_finger_tip_link">
        <visual>
            <geometry>
                <mesh filename="../robotiq_description/meshes/visual/robotiq_85_finger_tip_link.dae" />
            </geometry>
        </visual>
        <collision>
            <geometry>
                <mesh
                    filename="../robotiq_description/meshes/collision/robotiq_85_finger_tip_link.stl" />
            </geometry>
        </collision>
        <inertial>
            <mass value="0.019555" />
            <origin xyz="0.0 0.0 0.0" />
            <inertia ixx="0.000002" ixy="0.000000" ixz="0.000000" iyx="0.000000" iyy="0.000005"
                iyz="0.000000" izx="0.000000" izy="0.000000" izz="0.000006" />
        </inertial>
    </link>
    <!-- Improve grasping physics -->
    <gazebo reference="left_robotiq_85_left_finger_tip_link">
        <kp>1000000.0</kp>
        <kd>1.0</kd>
        <mu1>1.0</mu1>
        <mu2>1.0</mu2>
        <minDepth>0.001</minDepth>
    </gazebo>
    <gazebo reference="left_robotiq_85_right_finger_tip_link">
        <kp>1000000.0</kp>
        <kd>1.0</kd>
        <mu1>1.0</mu1>
        <mu2>1.0</mu2>
        <minDepth>0.001</minDepth>
    </gazebo>
    <transmission name="left_robotiq_85_left_knuckle_trans">
        <type>transmission_interface/SimpleTransmission</type>
        <joint name="left_robotiq_85_left_knuckle_joint">
            <hardwareInterface>hardware_interface/EffortJointInterface</hardwareInterface>
            <!-- <hardwareInterface>EffortJointInterface</hardwareInterface> -->
        </joint>
        <actuator name="left_robotiq_85_left_knuckle_motor">
            <mechanicalReduction>1</mechanicalReduction>
            <hardwareInterface>hardware_interface/EffortJointInterface</hardwareInterface>
            <!-- <hardwareInterface>EfforJointInterface</hardwareInterface> -->
        </actuator>
    </transmission>
    <!-- Mimic joints -->
    <gazebo>
        <plugin filename="libgazebo_mimic_joint_plugin.so" name="left_mimic_robotiq_85_1">
            <joint>left_robotiq_85_left_knuckle_joint</joint>
            <mimicJoint>left_robotiq_85_right_knuckle_joint</mimicJoint>
        </plugin>
        <plugin filename="libgazebo_mimic_joint_plugin.so" name="left_mimic_robotiq_85_2">
            <joint>left_robotiq_85_left_knuckle_joint</joint>
            <mimicJoint>left_robotiq_85_left_inner_knuckle_joint</mimicJoint>
        </plugin>
        <plugin filename="libgazebo_mimic_joint_plugin.so" name="left_mimic_robotiq_85_3">
            <joint>left_robotiq_85_left_knuckle_joint</joint>
            <mimicJoint>left_robotiq_85_right_inner_knuckle_joint</mimicJoint>
        </plugin>
        <plugin filename="libgazebo_mimic_joint_plugin.so" name="left_mimic_robotiq_85_4">
            <joint>left_robotiq_85_left_knuckle_joint</joint>
            <mimicJoint>left_robotiq_85_left_finger_tip_joint</mimicJoint>
            <multiplier>-1.0</multiplier>
            <offset>0.0</offset>
        </plugin>
        <plugin filename="libgazebo_mimic_joint_plugin.so" name="left_mimic_robotiq_85_5">
            <joint>left_robotiq_85_left_knuckle_joint</joint>
            <mimicJoint>left_robotiq_85_right_finger_tip_joint</mimicJoint>
            <multiplier>-1.0</multiplier>
            <offset>0.0</offset>
        </plugin>
    </gazebo>
</robot>